#VRML_SIM R2023a utf8

EXTERNPROTO "https://raw.githubusercontent.com/cyberbotics/webots/R2022b/projects/objects/backgrounds/protos/TexturedBackground.proto"
EXTERNPROTO "https://raw.githubusercontent.com/cyberbotics/webots/R2022b/projects/objects/backgrounds/protos/TexturedBackgroundLight.proto"
EXTERNPROTO "https://raw.githubusercontent.com/cyberbotics/webots/R2022b/projects/objects/floors/protos/RectangleArena.proto"

WorldInfo {
}
Viewpoint {
  orientation -0.008544849234465446 -0.0010505246280998913 -0.999962940288072 4.6606271881985215
  position 0.031697051033624794 -0.5671017978573424 0.061256738573256635
  follow "robot"
}
TexturedBackground {
}
TexturedBackgroundLight {
}
RectangleArena {
  floorSize 2 2
}
Robot {
  rotation 0 1 0 0
  children [
    DistanceSensor {
      translation 0 -0.05 0.03
      rotation 0 0 1 -1.5707953071795862
      name "ds1"
      recognitionColors [
        1 0 0
      ]
      type "laser"
    }
    DistanceSensor {
      translation 0.03 -0.05 0.03
      rotation 0 0 1 -0.9163003061004252
      name "ds2"
      recognitionColors [
        1 0 0
      ]
      type "laser"
    }
    DistanceSensor {
      translation -0.03 -0.04 0.03
      rotation 0 0 1 -2.2252996938995744
      name "ds3"
      recognitionColors [
        1 0 0
      ]
      type "laser"
    }
    DEF Body Transform {
      translation 0 0 0.0301
      children [
        Shape {
          appearance PBRAppearance {
            roughness 1
          }
          geometry Cylinder {
            height 0.05
            radius 0.05
          }
        }
      ]
    }
    HingeJoint {
      jointParameters HingeJointParameters {
        anchor 0.055 0 0.03
      }
      device [
        RotationalMotor {
          name "motor_1"
        }
      ]
      endPoint Solid {
        translation 0.055229279764097416 -4.427047951798458e-06 0.03004970938945427
        rotation 0 1 0 1.5707996938995747
        children [
          DEF Wheel Shape {
            appearance PBRAppearance {
              baseColor 0.4 0.4 0.4
              roughness 1
            }
            geometry Cylinder {
              height 0.01
              radius 0.025
            }
          }
        ]
        boundingObject USE Wheel
        physics DEF wheel_physics Physics {
        }
      }
    }
    HingeJoint {
      jointParameters HingeJointParameters {
        anchor -0.055 0 0.03
      }
      device [
        RotationalMotor {
          name "motor_2"
        }
      ]
      endPoint Solid {
        translation -0.0550000162917492 -4.92205711089888e-06 0.029996799903942335
        rotation -0.6624293393876601 -0.3498167885776644 -0.6624315698603425 3.814613740220351
        children [
          DEF Wheel Shape {
            appearance PBRAppearance {
              baseColor 0.4 0.4 0.4
              roughness 1
            }
            geometry Cylinder {
              height 0.01
              radius 0.025
            }
          }
        ]
        name "solid(1)"
        boundingObject USE Wheel
        physics DEF wheel_physics Physics {
        }
      }
    }
  ]
  boundingObject USE Body
  physics Physics {
    centerOfMass [
      0 0 0
    ]
  }
  controller "object_avoider_controller"
}
