#VRML_SIM R2023a utf8

EXTERNPROTO "https://raw.githubusercontent.com/cyberbotics/webots/R2022b/projects/objects/backgrounds/protos/TexturedBackground.proto"
EXTERNPROTO "https://raw.githubusercontent.com/cyberbotics/webots/R2022b/projects/objects/backgrounds/protos/TexturedBackgroundLight.proto"
EXTERNPROTO "https://raw.githubusercontent.com/cyberbotics/webots/R2023a/projects/objects/floors/protos/RectangleArena.proto"
EXTERNPROTO "https://raw.githubusercontent.com/cyberbotics/webots/R2023a/projects/objects/computers/protos/DesktopComputer.proto"

WorldInfo {
}
Viewpoint {
  orientation 0.4344180593394375 -0.3353461792748001 -0.8359568707568297 4.2657052333557886
  position -0.05592781361788013 -1.0491062018948485 1.446019608226701
  follow "robot"
}
TexturedBackground {
}
TexturedBackgroundLight {
}
Robot {
  translation -0.25 0 0
  rotation 0 1 0 0
  scale 3 3 3
  children [
    DistanceSensor {
      translation 0 -0.05 0.03
      rotation 0 0 1 -1.5707953071795862
      scale 2 2 2
      name "ds1"
    }
    DistanceSensor {
      translation 0 -0.05 0.03
      rotation 0 -0.3858999694561739 0.9225406297685343 -1.5707996938995747
      scale 2 2 2
      name "ds4"
    }
    DistanceSensor {
      translation 0.025 -0.045 0.03
      rotation 0 0 1 -0.9163003061004252
      scale 2 2 2
      name "ds2"
    }
    DistanceSensor {
      translation 0.04 -0.03 0.03
      rotation 0 0 1 -0.13090030610042527
      scale 2 2 2
      name "ds5"
    }
    DistanceSensor {
      translation -0.025 -0.045 0.03
      rotation 0 0 1 -2.2252996938995744
      scale 2 2 2
      name "ds3"
    }
    DistanceSensor {
      translation -0.04 -0.03 0.03
      rotation 0 0 1 -3.0106903061004253
      scale 2 2 2
      name "ds6"
    }
    DEF Body Transform {
      translation 0 0 0.0301
      children [
        Shape {
          appearance PBRAppearance {
            roughness 1
          }
          geometry Cylinder {
            height 0.05
            radius 0.05
          }
        }
      ]
    }
    HingeJoint {
      jointParameters HingeJointParameters {
        anchor 0.055 0 0.03
      }
      device [
        RotationalMotor {
          name "motor_1"
        }
      ]
      endPoint Solid {
        translation 0.055229279764097416 -4.427047951798458e-06 0.03004970938945427
        rotation 0 1 0 1.5707996938995747
        children [
          DEF Wheel Shape {
            appearance PBRAppearance {
              baseColor 0.4 0.4 0.4
              roughness 1
            }
            geometry Cylinder {
              height 0.01
              radius 0.025
            }
          }
        ]
        boundingObject USE Wheel
        physics DEF wheel_physics Physics {
        }
      }
    }
    HingeJoint {
      jointParameters HingeJointParameters {
        anchor -0.055 0 0.03
      }
      device [
        RotationalMotor {
          name "motor_2"
        }
      ]
      endPoint Solid {
        translation -0.0550000162917492 -4.92205711089888e-06 0.029996799903942335
        rotation -0.6624293393876608 -0.3498167885776642 -0.662431569860342 3.814613740220351
        children [
          DEF Wheel Shape {
            appearance PBRAppearance {
              baseColor 0.4 0.4 0.4
              roughness 1
            }
            geometry Cylinder {
              height 0.01
              radius 0.025
            }
          }
        ]
        name "solid(1)"
        boundingObject USE Wheel
        physics DEF wheel_physics Physics {
        }
      }
    }
  ]
  boundingObject USE Body
  physics Physics {
    centerOfMass [
      0 0 0
    ]
  }
  controller "object_avoider_controller"
}
RectangleArena {
  floorSize 4 2
  wallHeight 0.2
}
DesktopComputer {
  translation -1.04 -0.66 0
}
Solid {
  translation 0 0.73 0.19
  children [
    DEF Box Shape {
      appearance PBRAppearance {
      }
      geometry Box {
        size 0.3 0.3 0.3
      }
    }
  ]
  name "box"
  boundingObject USE Box
  physics Physics {
  }
}
Solid {
  translation -1.02 0.17 0.19
  children [
    DEF Box Shape {
      appearance PBRAppearance {
      }
      geometry Box {
        size 0.3 0.3 0.3
      }
    }
  ]
  name "box(2)"
  boundingObject USE Box
  physics Physics {
  }
}
Solid {
  translation 0.96 -0.1 0.19
  rotation 0 0 1 0.261799
  children [
    DEF Box Shape {
      appearance PBRAppearance {
      }
      geometry Box {
        size 0.3 0.3 0.3
      }
    }
  ]
  name "box(1)"
  boundingObject USE Box
  physics Physics {
  }
}
